Workbook

Sheet Summary
B2: Registered Pesticides Database — Bangladesh (up to 81st PTAC Meeting)
B4: Total Registered Products | D4: Crop-Pest Recommendations | G4: Unique Common Names | I4: Registration Holders
B5: 5452 | D5: 7250 | G5: 441 | I5: 879
B7: Products by Category
B8: Category | C8: Common Names | D8: Registered Products | E8: Recommendations
B9: Miticide | C9: 8 | D9: =COUNTA(Miticide!E5:E209) -> 205 | E9: =SUM(Miticide!L5:L209) -> 314
B10: Fungicide | C10: 103 | D10: =COUNTA(Fungicide!E5:E1056) -> 1052 | E10: =SUM(Fungicide!L5:L1056) -> 1543
B11: Insecticide | C11: 160 | D11: =COUNTA(Insecticide!E5:E2504) -> 2500 | E11: =SUM(Insecticide!L5:L2504) -> 3589
B12: Herbicide | C12: 68 | D12: =COUNTA(Herbicide!E5:E896) -> 892 | E12: =SUM(Herbicide!L5:L896) -> 984
B13: Store Grain Insecticide | C13: 3 | D13: =COUNTA('Store Grain Insecticide'!E5:E92) -> 88 | E13: =SUM('Store Grain Insecticide'!L5:L92) -> 91
B14: Rodenticide | C14: 2 | D14: =COUNTA(Rodenticide!E5:E19) -> 15 | E14: =SUM(Rodenticide!L5:L19) -> 15
B15: Bio Pesticide | C15: 20 | D15: =COUNTA('Bio Pesticide'!E5:E39) -> 35 | E15: =SUM('Bio Pesticide'!L5:L39) -> 42
B16: Public Health | C16: 77 | D16: =COUNTA('Public Health'!E5:E669) -> 665 | E16: =SUM('Public Health'!K5:K669) -> 672
B17: Total | C17: =SUM(C9:C16) -> 441 | D17: =SUM(D9:D16) -> 5452 | E17: =SUM(E9:E16) -> 7250
D18: =D17-D16 -> 4787
B20: Top 10 Registration Holders
B21: Companies/agencies with the most registered products
B22: # | C22: Name | D22: Products
B23: 1 | C23: ACI Formulations Limited | D23: 115
B24: 2 | C24: Haychem (Bangladesh) Limited | D24: 101
B25: 3 | C25: Sun Seed Pesticides | D25: 76
B26: 4 | C26: Intefa | D26: 62
B27: 5 | C27: Mimpex Agrochemicals Limited | D27: 61
B28: 6 | C28: Auto Crop Care Limited | D28: 59
B29: 7 | C29: McDonald Bangladesh (Pvt) Limited | D29: 58
B30: 8 | C30: Mamun Agro Products Ltd. | D30: 58
B31: 9 | C31: Valent Tech Limited | D31: 56
B32: 10 | C32: Bangladesh Agricultural Industries | D32: 53
B34: Top 10 Recommended Crops
B35: Crops with the most registered products (agricultural categories)
B36: # | C36: Name | D36: Products
B37: 1 | C37: Rice | D37: 1659
B38: 2 | C38: Tea | D38: 1598
B39: 3 | C39: Potato | D39: 473
B40: 4 | C40: Jute | D40: 420
B41: 5 | C41: Mango | D41: 391
B42: 6 | C42: Brinjal | D42: 281
B43: 7 | C43: Cotton | D43: 226
B44: 8 | C44: Tomato | D44: 204
B45: 9 | C45: Bean | D45: 153
...

Sheet README
B2: README — Registered Pesticides Database of Bangladesh
B4: About This Database
B5: Database | C5: Registered Pesticides of Bangladesh — approved up to the 81st Pesticide Technical Advisory Committee (PTAC) Meeting
B6: Issuing authority | C6: Department of Agricultural Extension (DAE), Ministry of Agriculture, Government of the People's Republic of Bangladesh
B7: Source page | C7: https://dae.gov.bd/pages/files/6922da2a933eb65569e02d1e (page title: "নিবন্ধিত বালাইনাশক" — Registered Pesticides, last updated 4 February 2024)
B8: Source document | C8: https://objectstorage.ap-dcc-gazipur-1.oraclecloud15.com/n/axvjbnqprylg/b/V2Ministry/o/office-dae/2024/12/7ad5aab9257b4eafbf8e15157f9bef18.pdf
B9: Extraction date | C9: 2026-09-15
B10: Scope | C10: 5,452 registered products (brands) across 8 categories, covering 7,247+ crop-pest recommendations, 441 unique common names (active ingredients/groups) and 879 registration holders
B12: Sheet Guide
B13: Summary | C13: Overview: totals by category, top registration holders, top crops and pests, registration number types, and a category chart
B14: Miticide / Fungicide / Insecticide / Herbicide / Store Grain Insecticide / Rodenticide / Bio Pesticide | C14: Agricultural pesticide categories — one row per registered product (brand)
B15: Public Health | C15: Household/public-health pesticide products (mosquito coils, aerosols, repellents, baits) — one row per registered product; no "Crops" column
B16: Review | C16: Self-check sheet: live formulas cross-check record counts against the source extraction; all rows should show PASS
B18: Column Definitions
B19: SL No (Common Name) | C19: Serial number of the common-name group within its category, as printed in the source list
B20: Common Name | C20: Chemical common name / active-ingredient group. In the source, this cell is merged across all products of the group, so it is repeated on every product row of that group here
B21: SL No (Products) | C21: Serial number of the product (brand) within its common-name group
B22: Brand Name | C22: Trade name of the registered product, including its formulation (e.g. "Taba 25WDG")
B23: Registration No | C23: Registration number printed in the source: AP-#### (agricultural), AP (Bio)-## (bio-pesticide), PHP-### (public health)
B24: Registration Holder | C24: Company or agency holding the registration
B25: Recommended Crops | C25: Crops for which the product is recommended (agricultural sheets only); multiple values are comma-separated
B26: Recommended Pests | C26: Target pests, diseases or weeds; multiple values are comma-separated
B27: Dosage Rate | C27: Distinct dosage rates, semicolon-separated (dosages may repeat across recommendations; see next column for the pairing)
B28: Recommendations (Crop | Pest | Dosage) | C28: One line per recommendation as printed in the source; a "-" marks a field left blank in the source
B29: No. of Recommendations | C29: Number of crop-pest(-dosage) lines printed for this product in the source
B31: How the Data Was Reconstructed
B32: Method | C32: The 189-page source PDF was parsed table-by-table with cell-level extraction (pdfplumber). Where the source table used merged cells, values were reconstructed as follows.
B33: Merged common names | C33: The common name (and its serial) is printed only on the first row of each group in the source; it was forward-filled to all products of the same group
B34: Merged recommendations | C34: When a recommendation line repeated the crop or pest of the line above (vertically merged cells), the missing field was inherited from the previous line; when the dosage cell was merged, the previous dosage applies
B35: Multi-line cells | C35: Where one cell contained several lines (e.g. two dosage lines), they were zipped into separate recommendations when the line counts aligned
B36: One row per product | C36: Each output row is one registered product (brand). All of its crop-pest-dosage lines are kept in the "Recommendations" column and summarised in the Crops / Pests / Dosage columns
B38: Data Quality Notes (source quirks, kept as printed)
B39: Typo registrations | C39: A few registration numbers contain source typos and are kept verbatim: "AP5615" (Nurzeb 80WP), "A-3375" (Abin 85WP), "AP--3368" (Umate 40EC), "AP--2277" (AP-Tap 57%), "AAP-4833" (Mita 33EC), "AP- 612" (Nuben 72WP), "PHP508" (Hit Super Mosquito Coil)
B40: Missing registrations | C40: One product (Golder Aerosol, S N Trade International, Public Health) has no registration number printed in the source
B41: Duplicate registrations | C41: 14 registration numbers are each assigned to two different products in the source (e.g. AP-3612 for both Gonder 50WP and Rosa 72SL); both rows are kept
B42: Missing pests | C42: AP-4472 (Marlo 2.5EC), AP-847 (Silah 500EC) and PHP-419 (Mosfly Cik Aerosol) have a blank pest and/or dosage cell in the source
B43: Serial gap | C43: The Store Grain Insecticide category jumps from serial 1 to 3 (no common name number 2 is printed in the source)
B44: Combined rows | C44: A handful of source rows squeeze two products into one line (e.g. "AP-2391 AP-2393 — Mascothrin 10EC / Korothrin 10EC"); these are kept as a single row with " / "-joined values where the source gives no way to split them
B45: Language | C45: All product data is printed in English in the source; the source page itself is in Bangla
B47: Provenance & Reuse
...

Sheet Miticide
B2: Registered Miticides in Bangladesh — up to 81st PTAC Meeting
B4: SL No (Common Name) | C4: Common Name | D4: SL No (Products) | E4: Brand Name | F4: Registration No | G4: Registration Holder | H4: Recommended Crops | I4: Recommended Pests | J4: Dosage Rate | K4: Recommendations (Crop | Pest | Dosage) | L4: No. of Recommendations | M4: MoA Code
B5: 1 | C5: Ethion | D5: 1 | E5: Pithion 46.5EC | F5: AP-5242 | G5: Padma Oil Company Ltd. | H5: Chilli | I5: Mites | J5: 2 ml/L of water | K5: Chilli | Mites | 2 ml/L of water | L5: 1 | M5: IRAC 1B
B6: 2 | C6: Ethion (5%) + Thiamethoxam (20%) | D6: 1 | E6: Taba 25WDG | F6: AP-4578 | G6: Alif Agro | H6: Chilli, Rice | I6: Thrips, Aphid, BPH | J6: 100 g/ha; 0.2 g/L of water | K6: Chilli | Thrips | 100 g/ha Chilli | Aphid | 0.2 g/L of water Rice | BPH | 100 g/ha | L6: 3 | M6: IRAC 1B
B7: 3 | C7: Fenpropathrin | D7: 1 | E7: Danitol 10EC | F7: AP-291 | G7: Shetu Corporation Limited | H7: Brinjal, Tea | I7: Red spider mite | J7: 1 ml/L of water; 1.00 L/ha | K7: Brinjal | Red spider mite | 1 ml/L of water Tea | Red spider mite | 1.00 L/ha | L7: 2 | M7: IRAC 3A
B8: 3 | C8: Fenpropathrin | D8: 2 | E8: Ritol 10EC | F8: AP-3509 | G8: Rajib Agro Chemicals Ltd. | H8: Tea | I8: Red spider mite | J8: 1.00 L/ha | K8: Tea | Red spider mite | 1.00 L/ha | L8: 1 | M8: IRAC 3A
B9: 3 | C9: Fenpropathrin | D9: 3 | E9: Dumet 10EC | F9: AP-4577 | G9: Mimpex Agrochemicals Limited | H9: Tea | I9: Red mite | J9: 1.00 L/ha | K9: Tea | Red mite | 1.00 L/ha | L9: 1 | M9: IRAC 3A
B10: 3 | C10: Fenpropathrin | D10: 4 | E10: Fenpro 10EC | F10: AP-4922 | G10: Oroni International Limited | H10: Tea | I10: Red spider mite | J10: 1.00 L/ha | K10: Tea | Red spider mite | 1.00 L/ha | L10: 1 | M10: IRAC 3A
B11: 3 | C11: Fenpropathrin | D11: 5 | E11: Samitol 10EC | F11: AP-5303 | G11: SAM Agro Chemical | H11: Chilli | I11: Aphid | J11: 2 ml/L of water | K11: Chilli | Aphid | 2 ml/L of water | L11: 1 | M11: IRAC 3A
B12: 3 | C12: Fenpropathrin | D12: 6 | E12: Unifen 20EC | F12: AP-5304 | G12: Unifarma Bangladesh Industries | H12: Tea | I12: Red Spider Mite | J12: 500 ml/ha | K12: Tea | Red Spider Mite | 500 ml/ha | L12: 1 | M12: IRAC 3A
B13: 3 | C13: Fenpropathrin | D13: 7 | E13: Fenpen 10EC | F13: AP-5305 | G13: S I Agro International | H13: Tea | I13: Red Spider Mite | J13: 1.00 L/ha | K13: Tea | Red Spider Mite | 1.00 L/ha | L13: 1 | M13: IRAC 3A
B14: 3 | C14: Fenpropathrin | D14: 8 | E14: Denethrin 10EC | F14: AP-5681 | G14: Bongshe Moharaj & Agro Technology | H14: Tea | I14: Red spider mite | J14: 1.00 L/ha | K14: Tea | Red spider mite | 1.00 L/ha | L14: 1 | M14: IRAC 3A
B15: 4 | C15: Fenpropathrin (3%) + Fenvalerate (7%) | D15: 1 | E15: Sniper 10SC | F15: AP-4565 | G15: Eminence Chemical Industries Ltd | H15: Tea | I15: Helopeltis | J15: 200 ml/ha | K15: Tea | Helopeltis | 200 ml/ha | L15: 1 | M15: IRAC 3A
B16: 5 | C16: Pyriproxyfen (5%) + Fenpropathrin (15%) | D16: 1 | E16: Sweetprid 20EC | F16: AP-4923 | G16: Sweet Agrovet Limited | H16: Brinjal | I16: Aphid | J16: 1 ml/L of water | K16: Brinjal | Aphid | 1 ml/L of water | L16: 1
B17: 5 | C17: Pyriproxyfen (5%) + Fenpropathrin (15%) | D17: 2 | E17: Nepathrin Plus 20EC | F17: AP-5306 | G17: Need Agro Industries | H17: Tea, Mango | I17: Red Spider Mite, Hopper | J17: 500 ml/ha; 1 ml/L of water | K17: Tea | Red Spider Mite | 500 ml/ha Mango | Hopper | 1 ml/L of water | L17: 2
B18: 5 | C18: Pyriproxyfen (5%) + Fenpropathrin (15%) | D18: 3 | E18: Super Win 20EC | F18: AP-5307 | G18: Win Agro Limited | H18: Tea | I18: Red Spider Mite | J18: 500 ml/ha | K18: Tea | Red Spider Mite | 500 ml/ha | L18: 1
B19: 5 | C19: Pyriproxyfen (5%) + Fenpropathrin (15%) | D19: 4 | E19: Jamir 20EC | F19: AP-5524 | G19: Intefa | H19: Jute | I19: Hairy Caterpillar | J19: 550 ml/ha | K19: Jute | Hairy Caterpillar | 550 ml/ha | L19: 1
B20: 5 | C20: Pyriproxyfen (5%) + Fenpropathrin (15%) | D20: 5 | E20: Plabon 20EC | F20: AP-5525 | G20: General Agro Chemicals Ltd. | H20: Brinjal | I20: Red Spider Mite | J20: 0.5 ml/L of water | K20: Brinjal | Red Spider Mite | 0.5 ml/L of water | L20: 1
B21: 5 | C21: Pyriproxyfen (5%) + Fenpropathrin (15%) | D21: 6 | E21: Fair-Hit 20EC | F21: AP-5779 | G21: Fair Agrochemicals Services Ltd. | H21: Mango, Tea | I21: Hopper, Helopeltis | J21: 1 ml/L of water; 500 ml/ha | K21: Mango | Hopper | 1 ml/L of water Tea | Helopeltis | 500 ml/ha | L21: 2
B22: 5 | C22: Pyriproxyfen (5%) + Fenpropathrin (15%) | D22: 7 | E22: Khallash 20EC | F22: AP-5780 | G22: Babylon Agriscience Ltd. | H22: Cotton | I22: Ball worm | J22: 200 ml/ha | K22: Cotton | Ball worm | 200 ml/ha | L22: 1
B23: 5 | C23: Pyriproxyfen (5%) + Fenpropathrin (15%) | D23: 8 | E23: ZicZole 20SC | F23: AP-6003 | G23: Gurpukur Corporation | H23: Jute | I23: Hairy Caterpillar | J23: 500 ml/ha | K23: Jute | Hairy Caterpillar | 500 ml/ha | L23: 1
B24: 5 | C24: Pyriproxyfen (5%) + Fenpropathrin (15%) | D24: 9 | E24: Serf Super 20EC | F24: AP-6004 | G24: Serf Agro Industroes | H24: Mango | I24: Hopper | J24: 1 ml/L of water | K24: Mango | Hopper | 1 ml/L of water | L24: 1
B25: 5 | C25: Pyriproxyfen (5%) + Fenpropathrin (15%) | D25: 10 | E25: Daoya 20EC | F25: AP-6005 | G25: Express Agro Care Ltd. | H25: Jute | I25: Hairy Caterpillar | J25: 650 ml/ha | K25: Jute | Hairy Caterpillar | 650 ml/ha | L25: 1
B26: 5 | C26: Pyriproxyfen (5%) + Fenpropathrin (15%) | D26: 11 | E26: Daze 20EC | F26: AP-6006 | G26: Roof Crop Care Ltd. | H26: Jute, Mango | I26: Hairy Caterpillar, Hopper | J26: 500 ml/ha; 1 ml/L of water | K26: Jute | Hairy Caterpillar | 500 ml/ha Mango | Hopper | 1 ml/L of water | L26: 2
B27: 5 | C27: Pyriproxyfen (5%) + Fenpropathrin (15%) | D27: 12 | E27: Rongon 20EC | F27: AP-6007 | G27: Valent Tech Limited | H27: Potato | I27: Cutworm | J27: 3 ml/L of water | K27: Potato | Cutworm | 3 ml/L of water | L27: 1
... B31: 5 | C31: Pyriproxyfen (5%) + Fenpropathrin (15%) | D31: 16 | E31: Ricofen Plus 20EC | F31: AP-6011 | G31: Rico Agrovet | H31: Tea | I31: Red spider mite | J31: 500 ml/ha | K31: Tea | Red spider mite | 500 ml/ha | L31: 1
B32: 6 | C32: Hexythiazox | D32: 1 | E32: Mite Scavenger 10EC | F32: AP-3898 | G32: Eminence Chemical Industries Ltd | H32: Tea | I32: Red spider mite | J32: 500 ml/ha | K32: Tea | Red spider mite | 500 ml/ha | L32: 1 | M32: IRAC 10A
B33: 6 | C33: Hexythiazox | D33: 2 | E33: Hexythiao 5.45EC | F33: AP-4076 | G33: Hossain Enterprise C C Ltd | H33: Tea, Brinjal | I33: Red spider mite, Mite | J33: 1.0 L/ha; 1 ml/L of water | K33: Tea | Red spider mite | 1.0 L/ha Brinjal | Mite | 1 ml/L of water | L33: 2 | M33: IRAC 10A
B34: 6 | C34: Hexythiazox | D34: 3 | E34: Larsimite 10EC | F34: AP-4576 | G34: Larsen Chemical Industries (Pvt) Ltd. | H34: Tea, Jute | I34: Red spider mite, Yellow mite | J34: 500 ml/ha | K34: Tea | Red spider mite | 500 ml/ha Jute | Yellow mite | 500 ml/ha | L34: 2 | M34: IRAC 10A
B35: 6 | C35: Hexythiazox | D35: 4 | E35: Demiter 10EC | F35: AP-4925 | G35: Win Agro Limited | H35: Tea, Rice | I35: Red spider mite, BPH | J35: 500 ml/ha; 1.0 L/ha | K35: Tea | Red spider mite | 500 ml/ha Rice | BPH | 1.0 L/ha | L35: 2 | M35: IRAC 10A
B36: 6 | C36: Hexythiazox | D36: 5 | E36: Nezox 10EC | F36: AP-4926 | G36: Need Agro Industries | H36: Tea, Rice | I36: Red spider mite, BPH | J36: 500 ml/ha; 1.0 L/ha | K36: Tea | Red spider mite | 500 ml/ha Rice | BPH | 1.0 L/ha | L36: 2 | M36: IRAC 10A
B37: 6 | C37: Hexythiazox | D37: 6 | E37: Mileage 10EC | F37: AP-5309 | G37: ACI Formulations Limited | H37: Tea, Chilli | I37: Red Spider Mite, Thrips | J37: 500 ml/ha; 1 ml/L of water | K37: Tea | Red Spider Mite | 500 ml/ha Chilli | Thrips | 1 ml/L of water | L37: 2 | M37: IRAC 10A
B38: 6 | C38: Hexythiazox | D38: 7 | E38: Aimzox 10EC | F38: AP-5311 | G38: Agricultural Input Marketing | H38: Tea, Jute | I38: Red spider mite, Yellow Mite | J38: 500 ml/ha; 800 ml/ha | K38: Tea | Red spider mite | 500 ml/ha Jute | Yellow Mite | 800 ml/ha | L38: 2 | M38: IRAC 10A
B39: 6 | C39: Hexythiazox | D39: 8 | E39: Sunex 10EC | F39: AP-5529 | G39: Sun Seed Pesticides | H39: Tea | I39: Red Spider Mite | J39: 500 ml/ha | K39: Tea | Red Spider Mite | 500 ml/ha | L39: 1 | M39: IRAC 10A
B40: 6 | C40: Hexythiazox | D40: 9 | E40: Spidex 10EC | F40: AP-5717 | G40: Hossain Enterprise C C Ltd | H40: Tea | I40: Red Spider Mite | J40: 500 ml/ha | K40: Tea | Red Spider Mite | 500 ml/ha | L40: 1 | M40: IRAC 10A
B41: 7 | C41: Propargite | D41: 1 | E41: Omite 57EC | F41: AP-184 | G41: Shetu Corporation Limited | H41: Tea, Brinjal | I41: Red spider mites, Red mite | J41: 1.0 L/ha | K41: Tea | Red spider mites | 1.0 L/ha Brinjal | Red mite | 1.0 L/ha | L41: 2 | M41: IRAC 12C
B42: 7 | C42: Propargite | D42: 2 | E42: Sumite 57EC | F42: AP-360 | G42: McDonald Bangladesh (Pvt) Limited | H42: Tea | I42: Red mites | J42: 1.0 L/ha | K42: Tea | Red mites | 1.0 L/ha | L42: 1 | M42: IRAC 12C
B43: 7 | C43: Propargite | D43: 3 | E43: Emimite 57EC | F43: AP-1159 | G43: Eminence Chemical Industries Ltd | H43: Tea | I43: Red spider mites | J43: 1.0 L/ha | K43: Tea | Red spider mites | 1.0 L/ha | L43: 1 | M43: IRAC 12C
... B47: 7 | C47: Propargite | D47: 7 | E47: Oromite 57EC | F47: AP-5351 | G47: Oroni International Limited | H47: Tea, Brinjal | I47: Red spider mites, Red mite | J47: 1.0 L/ha; 2 ml/L of water | K47: Tea | Red spider mites | 1.0 L/ha Brinjal | Red mite | 2 ml/L of water | L47: 2 | M47: IRAC 12C
B48: 8 | C48: Sulphur | D48: 1 | E48: Limi Sulphur 80WP | F48: AP-292 | G48: The Limit Agroproducts Limited | H48: Jute, Tea | I48: Yellow mites, Red mites | J48: 1.68 kg/ha; 2.20 kg/ha | K48: Jute | Yellow mites | 1.68 kg/ha Tea | Red mites | 2.20 kg/ha | L48: 2
...

Sheet Fungicide
B2: Registered Fungicides in Bangladesh — up to 81st PTAC Meeting
B4: SL No (Common Name) | C4: Common Name | D4: SL No (Products) | E4: Brand Name | F4: Registration No | G4: Registration Holder | H4: Recommended Crops | I4: Recommended Pests | J4: Dosage Rate | K4: Recommendations (Crop | Pest | Dosage) | L4: No. of Recommendations | M4: MoA Code
B5: 1 | C5: Azoxystrobin | D5: 1 | E5: Sitro 25 SC | F5: AP-3153 | G5: S I Agro International | H5: Tea | I5: Die back, Block rot | J5: 500 mlha | K5: Tea | Die back, Block rot | 500 mlha | L5: 1 | M5: FRAC 11
B6: 1 | C6: Azoxystrobin | D6: 2 | E6: Forbin 50WDG | F6: AP-3560 | G6: Sun Seed Pesticides | H6: Cucumber | I6: Powdery mildew | J6: 0.5 ml/L of water | K6: Cucumber | Powdery mildew | 0.5 ml/L of water | L6: 1 | M6: FRAC 11
B7: 1 | C7: Azoxystrobin | D7: 3 | E7: Forstrobin 25SC | F7: AP-4275 | G7: Forward International (BD) Ltd. | H7: Cucumber | I7: Powdery mildew | J7: 1 ml/L of water | K7: Cucumber | Powdery mildew | 1 ml/L of water | L7: 1 | M7: FRAC 11
B8: 1 | C8: Azoxystrobin | D8: 4 | E8: Affix 25SC | F8: AP-4691 | G8: RiceCo International Bangladesh Ltd | H8: Tea | I8: Die back | J8: 750 mlha | K8: Tea | Die back | 750 mlha | L8: 1 | M8: FRAC 11
B9: 1 | C9: Azoxystrobin | D9: 5 | E9: Azox 50WP | F9: AP-5054 | G9: McDonald Bangladesh (Pvt) Ltd. | H9: Sweet gourd | I9: Powdery mildew | J9: 0.5 g/L of water | K9: Sweet gourd | Powdery mildew | 0.5 g/L of water | L9: 1 | M9: FRAC 11
B10: 1 | C10: Azoxystrobin | D10: 6 | E10: Azomax 25SC | F10: AP-5360 | G10: Zaker Croplife Bangladesh | H10: Cucumbits, Cucumber, Tea | I10: Powdery mildew, Downy mildew, Black rot | J10: 1 ml/L of water; 500 mlha | K10: Cucumbits | Powdery mildew | 1 ml/L of water Cucumber | Downy mildew | 1 ml/L of water Tea | Black rot | 500 mlha | L10: 3 | M10: FRAC 11
B11: 2 | C11: Azoxystrobin (20% ) + Cyproconazole (8%) | D11: 1 | E11: Karishma 28SC | F11: AP-2431 | G11: Eon Agro Industries Limited | H11: Mango | I11: Anthracnose | J11: 1.2 L/ha | K11: Mango | Anthracnose | 1.2 L/ha | L11: 1 | M11: FRAC 11
B12: 2 | C12: Azoxystrobin (20% ) + Cyproconazole (8%) | D12: 2 | E12: Tared 280SC | F12: AP-3613 | G12: Intefa | H12: Potato | I12: Late blight | J12: 0.5 ml/L of water | K12: Potato | Late blight | 0.5 ml/L of water | L12: 1 | M12: FRAC 11
B13: 2 | C13: Azoxystrobin (20% ) + Cyproconazole (8%) | D13: 3 | E13: Dover 28SC | F13: AP-4245 | G13: Agritech | H13: Mango, Chilli | I13: Anthracnose | J13: 1 ml/L of water | K13: Mango | Anthracnose | 1 ml/L of water Chilli | Anthracnose | 1 ml/L of water | L13: 2 | M13: FRAC 11
B14: 2 | C14: Azoxystrobin (20% ) + Cyproconazole (8%) | D14: 4 | E14: Cauger 28SC | F14: AP-4692 | G14: RiceCo International Bangladesh Ltd | H14: Tea | I14: Die back | J14: 750 ml.ha | K14: Tea | Die back | 750 ml.ha | L14: 1 | M14: FRAC 11
B15: 2 | C15: Azoxystrobin (20% ) + Cyproconazole (8%) | D15: 5 | E15: Kasmira 28SC | F15: AP-4693 | G15: Mary Gold Agro Science | H15: Sweet gourd | I15: Powdery mildew | J15: 1 ml/L of water | K15: Sweet gourd | Powdery mildew | 1 ml/L of water | L15: 1 | M15: FRAC 11
B16: 2 | C16: Azoxystrobin (20% ) + Cyproconazole (8%) | D16: 6 | E16: Jinazole 28SC | F16: AP-4695 | G16: Alpha Agro Limited | H16: Sweet gourd, Wheat | I16: Powdery mildew, Leaf blight | J16: 1 ml/L of water | K16: Sweet gourd | Powdery mildew | 1 ml/L of water Wheat | Leaf blight | 1 ml/L of water | L16: 2 | M16: FRAC 11
... B91: 8 | C91: Boscalid (50%) | D91: 1 | E91: Sunca 50SC | F91: AP-5808 | G91: McDonald Bangladesh (Pvt) Limited | H91: Cucumber | I91: Powdery mildew | J91: 1 ml/L of water | K91: Cucumber | Powdery mildew | 1 ml/L of water | L91: 1 | M91: FRAC 7
B92: 9 | C92: Bismerthiazole | D92: 1 | E92: Bactrol 20WP | F92: AP-2567 | G92: Surovi Agro Industries Limited | H92: Potato | I92: Late blight | J92: 2 g/L of water | K92: Potato | Late blight | 2 g/L of water | L92: 1
B93: 9 | C93: Bismerthiazole | D93: 2 | E93: Bactroban 20WP | F93: AP-4218 | G93: Haychem (Bangladesh) Limited | H93: Tea, Potato, Rice, Tomato | I93: Red rust, Die back, Block rot, Wilt, Blast, Bacterial blight | J93: 2.00 kg/ha; 1.00 kg/h; 450 gg/ha; 2 g/L of water | K93: Tea | Red rust, Die back, Block rot | 2.00 kg/ha Potato | Wilt | 1.00 kg/h Rice | Blast, Bacterial blight | 450 gg/ha Tomato | Wilt | 2 g/L of water | L93: 4
B94: 9 | C94: Bismerthiazole | D94: 3 | E94: Radi 20WP | F94: AP-5012 | G94: Intefa | H94: Tomato | I94: Wilt | J94: 2 g/L of water | K94: Tomato | Wilt | 2 g/L of water | L94: 1
B95: 9 | C95: Bismerthiazole | D95: 4 | E95: Bismazol 20WP | F95: AP-5630 | G95: Square Pharmaceuticals Limited | H95: Tomato | I95: Wilt | J95: 2 g/L of water | K95: Tomato | Wilt | 2 g/L of water | L95: 1
B96: 10 | C96: Bismerthiazol (20%) + Kasungamycin (1.5%) | D96: 1 | E96: Sunoscar 21.5WP | F96: AP-5051 | G96: McDonald Bangladesh (Pvt) Limited | H96: Tea, Tomato | I96: Die Back, Wilt | J96: 1.5 Kg/ha; 2 g/L of water | K96: Tea | Die Back | 1.5 Kg/ha Tomato | Wilt | 2 g/L of water | L96: 2 | M96: FRAC 24
B97: 10 | C97: Bismerthiazol (20%) + Kasungamycin (1.5%) | D97: 2 | E97: Kimia 21.5WP | F97: AP-5375 | G97: Mimpex Agrochemicals Limited | H97: Tomato | I97: Wilt | J97: 2 g/L of water | K97: Tomato | Wilt | 2 g/L of water | L97: 1 | M97: FRAC 24
B98: 11 | C98: Carbendazim | D98: 1 | E98: Knowin 50WP | F98: AP-241 | G98: McDonald Bangladesh (Pvt) Limited | H98: Rice, Guava, Tea, Banana, Sugarcane, Mango | I98: Sheath blight, Anthracnose, Red rust, Black rot, Die back & Gall Ma, Sigatoka, Pine apple, Wilt & red rot | J98: 1.00 kg/ha; 2 g/L of water; 750 gm/ha; 1 ml/L of water | K98: Rice | Sheath blight | 1.00 kg/ha Guava | Anthracnose | 2 g/L of water Tea | Red rust, Black rot, Die back & Gall Ma | 750 gm/ha Banana | Sigatoka | 2 g/L of water Sugarcane | Pine apple, Wilt & red rot | 1 ml/L of water Mango | Anthracnose | 1 ml/L of water | L98: 6 | M98: FRAC 1
B99: 11 | C99: Carbendazim | D99: 2 | E99: Shincar 50WP | F99: AP-355 | G99: United Phosphorus (Bangladesh) Ltd. | H99: Tobacco | I99: Frog eye & Leaf spot | J99: 2 g/L of water | K99: Tobacco | Frog eye & Leaf spot | 2 g/L of water | L99: 1 | M99: FRAC 1
B100: 11 | C100: Carbendazim | D100: 3 | E100: Aimcozim 50WP | F100: AP-375 | G100: ACI Formulations Limited | H100: Rice, Tea, Sugarcane, Tomato | I100: Sheath blight, Red rust, Sett rot, Pineapple, Red rot & Wilt, Seedling rot | J100: 500 gm/ha; 750 gm/ha; 2 g/L of water | K100: Rice | Sheath blight | 500 gm/ha Tea | Red rust | 750 gm/ha Sugarcane | Sett rot, Pineapple | 500 gm/ha Sugarcane | Red rot & Wilt | 500 gm/ha Tomato | Seedling rot | 2 g/L of water | L100: 5 | M100: FRAC 1
B101: 11 | C101: Carbendazim | D101: 4 | E101: Agben 50%F | F101: AP-439 | G101: Genetica Industries Ltd. | H101: Sugarcane, Rice | I101: Sett treatment, Sheath blight | J101: 1 g/L of water; 1.00 kg/ha | K101: Sugarcane | Sett treatment | 1 g/L of water Rice | Sheath blight | 1.00 kg/ha | L101: 2 | M101: FRAC 1
B102: 11 | C102: Carbendazim | D102: 5 | E102: Forastin 50WP | F102: AP-511 | G102: Shetu Pesticides Limited | H102: Rice, Sugarcane | I102: Sheath blight, Sett rot | J102: 1.00 kg/ha; 1 g/L of water | K102: Rice | Sheath blight | 1.00 kg/ha Sugarcane | Sett rot | 1 g/L of water | L102: 2 | M102: FRAC 1
B103: 11 | C103: Carbendazim | D103: 6 | E103: Genuine 50WP | F103: AP-531 | G103: SAM Agro Chemical | H103: Sugarcane, Tomato, Rice, Garden pea, Mango, Chili | I103: Sett rot disease, Wilt, Sheath blight, Powdery mildew, Hopper, Anthracnose | J103: 1 g/L of water; 2 g/L of water; 1.00 kg/ha | K103: Sugarcane | Sett rot disease | 1 g/L of water Tomato | Wilt | 2 g/L of water Rice | Sheath blight | 1.00 kg/ha Garden pea | Powdery mildew | 2 g/L of water Mango | Hopper | 1 g/L of water Chili | Anthracnose | 2 g/L of water | L103: 6 | M103: FRAC 1
B104: 11 | C104: Carbendazim | D104: 7 | E104: Cindazim 50WP | F104: AP-627 | G104: Shetu Corporation Limited | H104: Tomato, Rice, Sugarcane | I104: Wilt, Sheath blight, Sett rot, Pineapple Red rot, Wilt | J104: 2 g/L of water; 1.00 kg/ha; 500 gm/ha | K104: Tomato | Wilt | 2 g/L of water Rice | Sheath blight | 1.00 kg/ha Sugarcane | Sett rot, Pineapple Red rot, Wilt | 500 gm/ha | L104: 3 | M104: FRAC 1
B105: 11 | C105: Carbendazim | D105: 8 | E105: Nayan 50WP | F105: AP-720 | G105: Anika Enterprise | H105: Tomato, Cabbage, Cauli, Sugarcane, Banana | I105: Seedling rot, Sett rot, Sigatoka | J105: 1 g/kg seed; 1 g/L of water | K105: Tomato, Cabbage, Cauli | Seedling rot | 1 g/kg seed Sugarcane | Sett rot | 1 g/L of water Banana | Sigatoka | 1 g/L of water | L105: 3 | M105: FRAC 1
B106: 11 | C106: Carbendazim | D106: 9 | E106: Zimper 50 WP | F106: AP-725 | G106: Prime Agro Limited | H106: Banana, Tomato | I106: Sigatoka, Wilt | J106: 2 g/L of water | K106: Banana | Sigatoka | 2 g/L of water Tomato | Wilt | 2 g/L of water | L106: 2 | M106: FRAC 1
B107: 11 | C107: Carbendazim | D107: 10 | E107: Evazim 50WP | F107: AP-729 | G107: E H & Agrovet Limited | H107: Rice, Sugarcane | I107: Sheath blight, Sett rot | J107: 1.00 kg/ha; 1 g/L of water | K107: Rice | Sheath blight | 1.00 kg/ha Sugarcane | Sett rot | 1 g/L of water | L107: 2 | M107: FRAC 1
... B244: 12 | C244: Carbendazim ( 32.5%) + Hexaconazole (2.5%) | D244: 2 | E244: Offense 35SC | F244: AP-4278 | G244: Popular Agro Industries | H244: Mango | I244: Anthracnose | J244: 0.5 ml/L of water | K244: Mango | Anthracnose | 0.5 ml/L of water | L244: 1 | M244: FRAC 1
C245: 40% + 5% | D245: 3 | E245: Dhan Shiri 45SC | F245: AP-5034 | G245: Sea Trade Fertilizer Limited | H245: Tea | I245: Dieback | J245: 750 ml/ha | K245: Tea | Dieback | 750 ml/ha | L245: 1
B246: 13 | C246: Carbendazin ( 20%) + Thiram (40%) | D246: 1 | E246: Topath 60WP | F246: AP-4720 | G246: Symbiosis Technology | H246: Tea | I246: Red Rust, Die Back, Block Rot | J246: 1.00 kg/ha | K246: Tea | Red Rust, Die Back, Block Rot | 1.00 kg/ha | L246: 1 | M246: FRAC 1
B247: 14 | C247: Carbendazim (25%) + Thiram (25%) Imidacloprid (25%) | D247: 1 | E247: Atavo 75WDG | F247: AP-4721 | G247: Annodatta Limited | H247: Tomato, Rice | I247: Wilt, Bakanae | J247: 8 g/kg Seed; 8 g/Kg Seed | K247: Tomato | Wilt | 8 g/kg Seed Rice | Bakanae | 8 g/Kg Seed | L247: 2 | M247: FRAC 1
B248: 14 | C248: Carbendazim (25%) + Thiram (25%) Imidacloprid (25%) | D248: 2 | E248: Nazda 75WDG | F248: AP-4722 | G248: Sasco International | H248: Tomato | I248: Wilt | J248: 8 g/kg Seed | K248: Tomato | Wilt | 8 g/kg Seed | L248: 1 | M248: FRAC 1
B249: 14 | C249: Carbendazim (25%) + Thiram (25%) Imidacloprid (25%) | D249: 3 | E249: Topzim Super 75WDG | F249: AP-4723 | G249: Tasin Agro Care | H249: Tomato, Rice | I249: Wilt, Bakanae | J249: 8 g/kg Seed; 8g/Kg Seed | K249: Tomato | Wilt | 8 g/kg Seed Rice | Bakanae | 8g/Kg Seed | L249: 2 | M249: FRAC 1
B250: 14 | C250: Carbendazim (25%) + Thiram (25%) Imidacloprid (25%) | D250: 4 | E250: Ama Plus 75WG | F250: AP-5036 | G250: Amana Agro Science | H250: Tea | I250: Dieback | J250: 500 gm/ha | K250: Tea | Dieback | 500 gm/ha | L250: 1 | M250: FRAC 1
B251: 14 | C251: Carbendazim (25%) + Thiram (25%) Imidacloprid (25%) | D251: 5 | E251: Naz Gold 75WDG | F251: AP-5037 | G251: Mondol Traders | H251: Bean | I251: Aphid | J251: 0. 2 gm/L of water | K251: Bean | Aphid | 0. 2 gm/L of water | L251: 1 | M251: FRAC 1
B252: 15 | C252: Carbendazim (10%) + Imidacloprid (10) + Metalaxyl (10%) | D252: 1 | E252: Fasal Special 30WP | F252: AP-5011 | G252: Fasal Agro Industries Ltd. | H252: Tea, Sweet gourd | I252: Helopeltis, Die back, Black rot, Powdery mildew | J252: 1.0 Kg/ha; 750 gm/ha; 250 gm/ha | K252: Tea | Helopeltis | 1.0 Kg/ha Tea | Die back, Black rot | 750 gm/ha Sweet gourd | Die back, Black rot | 750 gm/ha Sweet gourd | Powdery mildew | 250 gm/ha | L252: 4 | M252: FRAC 1
...

Sheet Insecticide
B2: Registered Insecticides in Bangladesh — up to 81st PTAC Meeting
B4: SL No (Common Name) | C4: Common Name | D4: SL No (Products) | E4: Brand Name | F4: Registration No | G4: Registration Holder | H4: Recommended Crops | I4: Recommended Pests | J4: Dosage Rate | K4: Recommendations (Crop | Pest | Dosage) | L4: No. of Recommendations | M4: MoA Code
B5: 1 | C5: Abamectin | D5: 1 | E5: Vertimec 1.8EC | F5: AP-890 | G5: Syngenta Bangladesh Limited | H5: Tea, Brinjal, Jujube, Litchi | I5: Red spider mite, Mite | J5: 1.25 L/ha; 1.20 L/ha; 1.25 ml/L of water | K5: Tea | Red spider mite | 1.25 L/ha Brinjal | Red spider mite | 1.20 L/ha Jujube, Litchi | Mite | 1.25 ml/L of water | L5: 3 | M5: IRAC 6
B6: 1 | C6: Abamectin | D6: 2 | E6: Abom 1.8EC | F6: AP-891 | G6: McDonald Crop Care Ltd. | H6: Tea, Rice, Brinjal | I6: Red spider mite, BPH | J6: 500 ml/ha; 1.2 ml/L of water | K6: Tea | Red spider mite | 500 ml/ha Rice | BPH | 500 ml/ha Brinjal | Red spider mite | 1.2 ml/L of water | L6: 3 | M6: IRAC 6
B7: 1 | C7: Abamectin | D7: 3 | E7: Abatin 1.8EC | F7: AP-1017 | G7: National AgriCare Import & Export Ltd | H7: Cotton | I7: Bollworm (Spotted & American) | J7: 1250-1500 ml/ha | K7: Cotton | Bollworm (Spotted & American) | 1250-1500 ml/ha | L7: 1 | M7: IRAC 6
B8: 1 | C8: Abamectin | D8: 4 | E8: Sunmectin 1.8EC | F8: AP-1034 | G8: Auto Crop Care Limited | H8: Tea, Cotton, Rice, Brinjal | I8: Red spider mite, Helopeltis (Mosquito bug), Bollworm, Aphid, Jassid, BPH, Red spider mites | J8: 1.25 L/ha; 1.20 L/ha; 1.50 L/ha; 1.0 L/ha; 1.20 ml/L of water | K8: Tea | Red spider mite | 1.25 L/ha Tea | Helopeltis (Mosquito bug) | 1.20 L/ha Cotton | Bollworm, Aphid, Jassid | 1.50 L/ha Rice | BPH | 1.0 L/ha Brinjal | Red spider mites | 1.20 ml/L of water | L8: 5 | M8: IRAC 6
B9: 1 | C9: Abamectin | D9: 5 | E9: Kraft 1.8EC | F9: AP-1141 | G9: Oroni International Limited | H9: Brinjal | I9: Red spider mite | J9: 1.20 ml/L of water | K9: Brinjal | Red spider mite | 1.20 ml/L of water | L9: 1 | M9: IRAC 6
B10: 1 | C10: Abamectin | D10: 6 | E10: Toptin 1.8EC | F10: AP-1153 | G10: East West Chemicals Ltd. | H10: Rice | I10: BPH & Hispa | J10: 1.0 L/ha | K10: Rice | BPH & Hispa | 1.0 L/ha | L10: 1 | M10: IRAC 6
B11: 1 | C11: Abamectin | D11: 7 | E11: Licar 1.8EC | F11: AP-1206 | G11: Corbel International Limited | H11: Rice | I11: BPH & Hispa | J11: 1.0 L/ha | K11: Rice | BPH & Hispa | 1.0 L/ha | L11: 1 | M11: IRAC 6
B12: 1 | C12: Abamectin | D12: 8 | E12: Ambush 1.8EC | F12: AP-1241 | G12: Haychem (Bangladesh) Limited | H12: Tea, Rice, Brinjal | I12: Red spider mite, BPH | J12: 1.25 L/ha; 1.0 L/ha; 1.20 ml/L of water | K12: Tea | Red spider mite | 1.25 L/ha Rice | BPH | 1.0 L/ha Brinjal | Red spider mite | 1.20 ml/L of water | L12: 3 | M12: IRAC 6
B13: 1 | C13: Abamectin | D13: 9 | E13: Lakad 1.8EC | F13: AP-1282 | G13: Intefa | H13: Tea, Brinjal | I13: Red spider mite | J13: 1.25 L/ha; 1.20 ml/Lof water | K13: Tea | Red spider mite | 1.25 L/ha Brinjal | Red spider mite | 1.20 ml/Lof water | L13: 2 | M13: IRAC 6
B14: 1 | C14: Abamectin | D14: 10 | E14: Acamite 1.8EC | F14: AP-1286 | G14: ACI Formulations Limited | H14: Tea, Rice | I14: Red spider mite, BPH | J14: 1.25 L/ha; 1.00 L/ha | K14: Tea | Red spider mite | 1.25 L/ha Rice | BPH | 1.00 L/ha | L14: 2 | M14: IRAC 6
B15: 1 | C15: Abamectin | D15: 11 | E15: Alba 1.8EC | F15: AP-1467 | G15: SAMP Limited | H15: Rice | I15: BPH, Hispa | J15: 1.00 L/ha | K15: Rice | BPH, Hispa | 1.00 L/ha | L15: 1 | M15: IRAC 6
B16: 1 | C16: Abamectin | D16: 12 | E16: Iprotin 1.8EC | F16: AP-1509 | G16: Surovi Agro Industries Limited | H16: Tea | I16: Red spider mite | J16: 500 ml/ha | K16: Tea | Red spider mite | 500 ml/ha | L16: 1 | M16: IRAC 6
... B135: 2 | C135: Abamectin (1%) + acetamiprid (3%) | D135: 10 | E135: Forway 4EC | F135: AP-4918 | G135: Forward International (BD) Ltd. | H135: Rice | I135: BPH | J135: 1.0 L/ha | K135: Rice | BPH | 1.0 L/ha | L135: 1 | M135: IRAC 6
C136: (1.80%) + (15.00%) | D136: 11 | E136: Keratin 4EC | F136: AP-4919 | G136: Nafis Crop Care | H136: Rice | I136: BPH | J136: 1.0 L/ha | K136: Rice | BPH | 1.0 L/ha | L136: 1
C137: (1.80%) + (15.00%) | D137: 12 | E137: Sunabaprid 4EC | F137: AP-5230 | G137: McDonald Bangladesh (Pvt) Limited | H137: Tea, Brinjal | I137: Red spider mite | J137: 500 ml/ha; 1 ml/L of water | K137: Tea | Red spider mite | 500 ml/ha Brinjal | Red spider mite | 1 ml/L of water | L137: 2
C138: (1.80%) + (15.00%) | D138: 13 | E138: Descopritin 4EC | F138: AP-5562 | G138: Desh Agro Services Company Ltd. | H138: Rice | I138: BPH | J138: 1.0 L/ha | K138: Rice | BPH | 1.0 L/ha | L138: 1
C139: (1.80%) + (15.00%) | D139: 14 | E139: Abaprid 4EC | F139: AP-5563 | G139: Nature & Care Agro Products Ltd. | H139: Rice | I139: BPH | J139: 1.0 L/ha | K139: Rice | BPH | 1.0 L/ha | L139: 1
C140: (1.80%) + (15.00%) | D140: 15 | E140: Impede Plus 16.80EC | F140: AP-5565 | G140: Fasal Agro Industries Ltd | H140: Tea | I140: Red spider mite | J140: 250 ml/ | K140: Tea | Red spider mite | 250 ml/ | L140: 1
C141: (1.80%) + (15.00%) | D141: 16 | E141: Carbotin 4EC | F141: AP-5715 | G141: ICI Agri Care | H141: Brinjal | I141: Aphid | J141: 0.3 ml/L of water | K141: Brinjal | Aphid | 0.3 ml/L of water | L141: 1
C142: (1.80%) + (15.00%) | D142: 17 | E142: Faand 4EC | F142: AP-5901 | G142: Farmtech Bangladesh | H142: Rice | I142: BPH | J142: 1.0 L/ha | K142: Rice | BPH | 1.0 L/ha | L142: 1
B143: 3 | C143: Abamectin (1%) + Beta Cypermethrin (2%) | D143: 1 | E143: Emithrin Plus 3WDG | F143: AP-2066 | G143: Eminence Chemical Industries Ltd | H143: Tea | I143: Helopeltis | J143: 1 g/Lof water | K143: Tea | Helopeltis | 1 g/Lof water | L143: 1 | M143: IRAC 6
B144: 3 | C144: Abamectin (1%) + Beta Cypermethrin (2%) | D144: 2 | E144: Abaryl 3WDG | F144: AP-3507 | G144: Rahman Pesticide & Chemicals Co. | H144: Cotton | I144: Aphid, Jassid, Bollworm | J144: 100 gm/ha | K144: Cotton | Aphid, Jassid, Bollworm | 100 gm/ha | L144: 1 | M144: IRAC 6
B145: 3 | C145: Abamectin (1%) + Beta Cypermethrin (2%) | D145: 3 | E145: Aabata 3WDG | F145: AP-3508 | G145: Sweet Agrovet Limited | H145: Cotton | I145: Aphid, Jassid, Bollworm | J145: 100 gm/ha | K145: Cotton | Aphid, Jassid, Bollworm | 100 gm/ha | L145: 1 | M145: IRAC 6
B146: 3 | C146: Abamectin (1%) + Beta Cypermethrin (2%) | D146: 4 | E146: Betathrin 3WDG | F146: AP-3878 | G146: FIK Agro Products | H146: Country Bean | I146: Aphid | J146: 1 g/Lof water | K146: Country Bean | Aphid | 1 g/Lof water | L146: 1 | M146: IRAC 6
B147: 3 | C147: Abamectin (1%) + Beta Cypermethrin (2%) | D147: 5 | E147: Fasthrin 3WDG | F147: AP-3879 | G147: Fasal Agro Industries Ltd | H147: Tea | I147: Aphid | J147: 500 gm/ha | K147: Tea | Aphid | 500 gm/ha | L147: 1 | M147: IRAC 6
B148: 3 | C148: Abamectin (1%) + Beta Cypermethrin (2%) | D148: 6 | E148: Vico Plus 3WDG | F148: AP-3881 | G148: Nahar Agro International | H148: Country Bean, Tea | I148: Aphid, Red spider mite | J148: 0.5 gl/L of water; 1.25 Kg/ha | K148: Country Bean | Aphid | 0.5 gl/L of water Tea | Red spider mite | 1.25 Kg/ha | L148: 2 | M148: IRAC 6
B149: 3 | C149: Abamectin (1%) + Beta Cypermethrin (2%) | D149: 7 | E149: Goldimithrin Plus 3WDG | F149: AP-3882 | G149: Golden Agro Chemicals Limited | H149: Country Bean | I149: Aphid | J149: 1 g/Lof water | K149: Country Bean | Aphid | 1 g/Lof water | L149: 1 | M149: IRAC 6
B150: 3 | C150: Abamectin (1%) + Beta Cypermethrin (2%) | D150: 8 | E150: Pathrin 3WDG | F150: AP-3883 | G150: Marshal Agrovet Chemical Industries Ltd. | H150: Country Bean | I150: Aphid | J150: 1 g/Lof water | K150: Country Bean | Aphid | 1 g/Lof water | L150: 1 | M150: IRAC 6
B151: 3 | C151: Abamectin (1%) + Beta Cypermethrin (2%) | D151: 9 | E151: Ayesha 3WGD | F151: AP-4013 | G151: Genetica Industries Ltd. | H151: Tea | I151: Helopeltis | J151: 1.25 Kg/ha | K151: Tea | Helopeltis | 1.25 Kg/ha | L151: 1 | M151: IRAC 6
B152: 3 | C152: Abamectin (1%) + Beta Cypermethrin (2%) | D152: 10 | E152: Betatin 3WDG | F152: AP-4014 | G152: Aranya Crop Care Limited | H152: Tea, Potato | I152: Helopeltis, Aphid | J152: 1.25 Kg/ha; 0.5 gl/L of water | K152: Tea | Helopeltis | 1.25 Kg/ha Potato | Aphid | 0.5 gl/L of water | L152: 2 | M152: IRAC 6
B153: 3 | C153: Abamectin (1%) + Beta Cypermethrin (2%) | D153: 11 | E153: Adam Plus 3WDG | F153: AP-4015 | G153: Krishi Crop Care Limited | H153: Tea | I153: Helopeltis | J153: 1.25 Kg/ha | K153: Tea | Helopeltis | 1.25 Kg/ha | L153: 1 | M153: IRAC 6
B154: 3 | C154: Abamectin (1%) + Beta Cypermethrin (2%) | D154: 12 | E154: Achamka 3WDG | F154: AP-4016 | G154: Gurpukur Corporation | H154: Tea, Brinjal | I154: Aphid | J154: 500 gm/ha; 0.5 gl/L of water | K154: Tea | Aphid | 500 gm/ha Brinjal | Aphid | 0.5 gl/L of water | L154: 2 | M154: IRAC 6
... B171: 3 | C171: Abamectin (1%) + Beta Cypermethrin (2%) | D171: 29 | E171: Magot 3WDG | F171: AP-4533 | G171: Mosco Marketing Company | H171: Tea | I171: Aphid | J171: 500 gm/ha | K171: Tea | Aphid | 500 gm/ha | L171: 1 | M171: IRAC 6
C172: (0.6% + 1.55%) | D172: 30 | E172: Tufan 3WDG | F172: AP-4534 | G172: SARK Bangladesh | H172: Tea, Bean | I172: Helopeltis, Aphid | J172: 1.25 Kg/ha; 1 g/Lof water | K172: Tea | Helopeltis | 1.25 Kg/ha Bean | Aphid | 1 g/Lof water | L172: 2
C173: (0.6% + 1.55%) | D173: 31 | E173: Dimithrin Plus 3WDG | F173: AP-4535 | G173: D M Crop Care Limited | H173: Tea, Mango | I173: Helopeltis, Hopper | J173: 1.25 Kg/ha; 1 g/Lof water | K173: Tea | Helopeltis | 1.25 Kg/ha Mango | Hopper | 1 g/Lof water | L173: 2
C174: (0.6% + 1.55%) | D174: 32 | E174: M-Thrin Plus 3WDG | F174: AP-4536 | G174: Mamun Agro Products Ltd. | H174: Tea | I174: Aphid | J174: 500 gm/ha | K174: Tea | Aphid | 500 gm/ha | L174: 1
C175: (0.6% + 1.55%) | D175: 33 | E175: SB Marvel 3WDG | F175: AP-4930 | G175: SB Crop Care Industries Ltd. | H175: Bean | I175: Aphid | J175: 1 g/Lof water | K175: Bean | Aphid | 1 g/Lof water | L175: 1
C176: (0.6% + 1.55%) | D176: 34 | E176: Operation 3WDG | F176: AP-4931 | G176: Jass Agro Limited | H176: Tea | I176: Red spider mite | J176: 500 gm/ha | K176: Tea | Red spider mite | 500 gm/ha | L176: 1
...

Sheet Herbicide
B2: Registered Herbicides in Bangladesh — up to 81st PTAC Meeting
B4: SL No (Common Name) | C4: Common Name | D4: SL No (Products) | E4: Brand Name | F4: Registration No | G4: Registration Holder | H4: Recommended Crops | I4: Recommended Pests | J4: Dosage Rate | K4: Recommendations (Crop | Pest | Dosage) | L4: No. of Recommendations | M4: MoA Code
B5: 1 | C5: 2,4-D Amine | D5: 1 | E5: U 46 D Fluid | F5: AP-243 | G5: BASF Bangladesh Limited | H5: Tea | I5: Mikania creeper, Bagracote | J5: 3.00 L/ha | K5: Tea | Mikania creeper, Bagracote | 3.00 L/ha | L5: 1 | M5: HRAC O
B6: 1 | C6: 2,4-D Amine | D6: 2 | E6: Kem Amin 58SL | F6: AP-482 | G6: Hossain Enterprises C.C. Ltd | H6: Tea | I6: Weed (Dicot) | J6: 2.80 L/ha | K6: Tea | Weed (Dicot) | 2.80 L/ha | L6: 1 | M6: HRAC O
B7: 1 | C7: 2,4-D Amine | D7: 3 | E7: Fielder 48SL | F7: AP-494 | G7: ACI Formulations Limited | H7: Tea, Wheat | I7: Weed (Dicot), C. album, O.europace, R.maritimus, V.hirsuta | J7: 2.80 L/ha | K7: Tea | Weed (Dicot) | 2.80 L/ha Wheat | C. album, O.europace, R.maritimus, V.hirsuta | 2.80 L/ha | L7: 2 | M7: HRAC O
B8: 1 | C8: 2,4-D Amine | D8: 4 | E8: Weedkill 480SL | F8: AP-702 | G8: SAM Agro Chemical | H8: Tea | I8: Weed (Dicot) | J8: 2.80 L/ha | K8: Tea | Weed (Dicot) | 2.80 L/ha | L8: 1 | M8: HRAC O
B9: 1 | C9: 2,4-D Amine | D9: 5 | E9: Salix | F9: AP-929 | G9: Hiron Agro Limited | H9: Rice | I9: Monochoria vaginalis, Ludwigia, octovalvis, Sphenoclea zeylanica | J9: 450 g/acare | K9: Rice | Monochoria vaginalis, Ludwigia, octovalvis, Sphenoclea zeylanica | 450 g/acare | L9: 1 | M9: HRAC O
B10: 1 | C10: 2,4-D Amine | D10: 6 | E10: Weed Clean 480SL | F10: AP-1196 | G10: Eminence Chemical Industries Ltd | H10: Tea | I10: Broad leaves | J10: 2.24 L/ha | K10: Tea | Broad leaves | 2.24 L/ha | L10: 1 | M10: HRAC O
B11: 1 | C11: 2,4-D Amine | D11: 7 | E11: 2,4-D Weeder | F11: AP-1197 | G11: McDonald Bangladesh (Pvt) Limited | H11: Tea | I11: Broad leaves | J11: 2.24 L/ha | K11: Tea | Broad leaves | 2.24 L/ha | L11: 1 | M11: HRAC O
B12: 1 | C12: 2,4-D Amine | D12: 8 | E12: Filder Plus 48SL | F12: AP-2272 | G12: ACI Formulations Limited | H12: Tea | I12: Dicot | J12: 2.80 L/ha | K12: Tea | Dicot | 2.80 L/ha | L12: 1 | M12: HRAC O
B13: 1 | C13: 2,4-D Amine | D13: 9 | E13: Bonmara 480SL | F13: AP-2273 | G13: East West Chemicals Ltd. | H13: Tea | I13: Dicot | J13: 2.80 L/ha | K13: Tea | Dicot | 2.80 L/ha | L13: 1 | M13: HRAC O
B14: 1 | C14: 2,4-D Amine | D14: 10 | E14: Just 48SL | F14: AP-2274 | G14: Sun Seed Pesticides | H14: Tea | I14: Dicot | J14: 2.80 L/ha | K14: Tea | Dicot | 2.80 L/ha | L14: 1 | M14: HRAC O
B15: 1 | C15: 2,4-D Amine | D15: 11 | E15: Chiruni 72SL | F15: AP-2547 | G15: Aama Green Care | H15: Tea | I15: Dicot, Monocot | J15: 2.80 L/ha | K15: Tea | Dicot, Monocot | 2.80 L/ha | L15: 1 | M15: HRAC O
B16: 1 | C16: 2,4-D Amine | D16: 12 | E16: Totomine 72SL | F16: AP-2548 | G16: Home Pest Control | H16: Tea | I16: Dicot, Monocot | J16: 2.80 L/ha | K16: Tea | Dicot, Monocot | 2.80 L/ha | L16: 1 | M16: HRAC O
... B107: 5 | C107: Bensulfuron methyl (4%) + Acetochlor (14%) | D107: 63 | E107: TP-Link 18WP | F107: AP-5179 | G107: ADR Crop Care | H107: Tea | I107: B.hispida, I.cylindrica | J107: 3.00 kg/ha | K107: Tea | B.hispida, I.cylindrica | 3.00 kg/ha | L107: 1 | M107: HRAC B
C108: (26% + 4%) | D108: 64 | E108: Serfclean 18WP | F108: AP-5181 | G108: Serf Agro Industries | H108: Tea | I108: B.hispida, I.cylindrica | J108: 3.00 kg/ha | K108: Tea | B.hispida, I.cylindrica | 3.00 kg/ha | L108: 1
C109: (26% + 4%) | D109: 65 | E109: Superfine 18WP | F109: AP-5182 | G109: Super Crop Care Ltd. | H109: Tea | I109: B.hispida, I.cylindrica | J109: 3.00 kg/ha | K109: Tea | B.hispida, I.cylindrica | 3.00 kg/ha | L109: 1
C110: (26% + 4%) | D110: 66 | E110: Dix 18WP | F110: AP-5183 | G110: Agro Link BD | H110: Tea | I110: B.hispida, I.cylindrica | J110: 3.00 kg/ha | K110: Tea | B.hispida, I.cylindrica | 3.00 kg/ha | L110: 1
C111: (26% + 4%) | D111: 67 | E111: Sky Blue 18WP | F111: AP-5184 | G111: The Sky Agro Products | H111: Tea | I111: B.hispida, I.cylindrica | J111: 3.00 kg/ha | K111: Tea | B.hispida, I.cylindrica | 3.00 kg/ha | L111: 1
C112: (26% + 4%) | D112: 68 | E112: Bendar 18WP | F112: AP-5185 | G112: Super Agro Services Co. Ltd. | H112: Onion | I112: E. crus-galli, C. rotundus, D. san | J112: 2.5 Kg/ha | K112: Onion | E. crus-galli, C. rotundus, D. san | 2.5 Kg/ha | L112: 1
C113: (26% + 4%) | D113: 69 | E113: Georjerice Gold 18WP | F113: AP-5186 | G113: Kohinoor Agro Chemicals | H113: Rice | I113: E. crus-galli, M.vaginalis | J113: 750 g/ha | K113: Rice | E. crus-galli, M.vaginalis | 750 g/ha | L113: 1
C114: (26% + 4%) | D114: 70 | E114: Boomer 18WP | F114: AP-5187 | G114: Agro Business Support Ltd. | H114: Rice | I114: E. crus-galli, M.vaginalis, S.maritimus, C. difformis | J114: 750 gm/ha | K114: Rice | E. crus-galli, M.vaginalis, S.maritimus, C. difformis | 750 gm/ha | L114: 1
C115: (26% + 4%) | D115: 71 | E115: Lalteer 18WP | F115: AP-5189 | G115: Chens Crop Science Bangladesh Ltd. | H115: Rice | I115: E. crus-galli, M.vaginalis, S.maritimus, C. difformis | J115: 750 gm/ha | K115: Rice | E. crus-galli, M.vaginalis, S.maritimus, C. difformis | 750 gm/ha | L115: 1
C116: (26% + 4%) | D116: 72 | E116: Naingla 18WP | F116: AP-5190 | G116: Evergreen Crop Care Limited | H116: Rice | I116: E. crus-galli, M.vaginalis, S.maritimus, C. difformis | J116: 750 gm/ha | K116: Rice | E. crus-galli, M.vaginalis, S.maritimus, C. difformis | 750 gm/ha | L116: 1
C117: (26% + 4%) | D117: 73 | E117: Palam 18WP | F117: AP-5191 | G117: Pafs Agro International Co. | H117: Rice | I117: E. crus-galli, M.vaginalis, S.maritimus, C. difformis | J117: 750 gm/ha | K117: Rice | E. crus-galli, M.vaginalis, S.maritimus, C. difformis | 750 gm/ha | L117: 1
C118: (26% + 4%) | D118: 74 | E118: Luxed 18WP | F118: AP-5192 | G118: Luxury Agro Limited | H118: Rice | I118: E. crus-galli, M.vaginalis, S.maritimus, C. difformis | J118: 750 gm/ha | K118: Rice | E. crus-galli, M.vaginalis, S.maritimus, C. difformis | 750 gm/ha | L118: 1
C119: (26% + 4%) | D119: 75 | E119: Dibar 18WP | F119: AP-5194 | G119: SAM Agro Chemical | H119: Rice | I119: E. crus-galli, M.vaginalis, S.maritimus, C. difformis | J119: 750 gm/ha | K119: Rice | E. crus-galli, M.vaginalis, S.maritimus, C. difformis | 750 gm/ha | L119: 1
... C163: (26% + 4%) | D163: 119 | E163: Agacha Clear 18WP | F163: AP-6098 | G163: Chashi Agro Care | H163: Rice | I163: E. crus-galli, M.vaginalis, S.maritimus, C. difformis | J163: 500 g/ha | K163: Rice | E. crus-galli, M.vaginalis, S.maritimus, C. difformis | 500 g/ha | L163: 1
B164: 6 | C164: Chloropropham (50%) | D164: 1 | E164: Oorja 50HN | F164: AP-5200 | G164: RiceCo International Bangladesh Ltd. | H164: Potato | I164: Anti Sprouting, agemt | J164: 40 ml/Ton | K164: Potato | Anti Sprouting, agemt | 40 ml/Ton | L164: 1 | M164: HRAC K2
B165: 7 | C165: Bensulfuron methyl (0.6%) + Pretilachlor (6%%) (6% + 34%) | D165: 1 | E165: Londax Powder 6.6GR | F165: AP-2111 | G165: Petrochem Agro Industries Ltd. | H165: Rice | I165: S. maritimus, E. crus-galli, M.vaginalis, L. octovalvis, D. trifolium, M. minuta, C. difformis, S. zeylanica | J165: 9.88 kg/ha | K165: Rice | S. maritimus, E. crus-galli, M.vaginalis, L. octovalvis, D. trifolium, M. minuta, C. difformis, S. zeylanica | 9.88 kg/ha | L165: 1 | M165: HRAC B
B166: 8 | C166: Bensulfuron methyl (3%) + Mefenacet (50%) | D166: 1 | E166: Super Clean 53WP | F166: AP-1175 | G166: National AgriCare Import & Export Ltd | H166: Rice | I166: Weeds | J166: 450 gm/ha | K166: Rice | Weeds | 450 gm/ha | L166: 1 | M166: HRAC B
B167: 8 | C167: Bensulfuron methyl (3%) + Mefenacet (50%) | D167: 2 | E167: Clean Master 53 WP | F167: AP-3182 | G167: Haychem (Bangladesh) Limited | H167: Rice | I167: Q. europea, M.vaginalis, C.difformis | J167: 1.10 kg/ha | K167: Rice | Q. europea, M.vaginalis, C.difformis | 1.10 kg/ha | L167: 1 | M167: HRAC B
B168: 8 | C168: Bensulfuron methyl (3%) + Mefenacet (50%) | D168: 3 | E168: Ghash Killer 53WP | F168: AP-4416 | G168: Sweet Agrovet Limited | H168: Rice | I168: E. crus-galli, M.vaginalis, C.difformis, S. maritimus | J168: 620 gm/ha | K168: Rice | E. crus-galli, M.vaginalis, C.difformis, S. maritimus | 620 gm/ha | L168: 1 | M168: HRAC B
B169: 8 | C169: Bensulfuron methyl (3%) + Mefenacet (50%) | D169: 4 | E169: Relief 53WP | F169: AP-4417 | G169: Eon Agro Industries Limited | H169: Rice | I169: E. crus-galli, M.vaginalis, M. quadrifolia, S. maritimus | J169: 800 gm/ha | K169: Rice | E. crus-galli, M.vaginalis, M. quadrifolia, S. maritimus | 800 gm/ha | L169: 1 | M169: HRAC B
B170: 8 | C170: Bensulfuron methyl (3%) + Mefenacet (50%) | D170: 5 | E170: Get-Clean 69WP | F170: AP-4418 | G170: Getco Agri Technologies Ltd. | H170: Rice | I170: M.vaginalis, M. quadrifolia, S. maritimus | J170: 700 gm/ha | K170: Rice | M.vaginalis, M. quadrifolia, S. maritimus | 700 gm/ha | L170: 1 | M170: HRAC B
B171: 9 | C171: Bensulfuron methyl (4%) + Quinclorac (28%) (6% + 34%) (6% + 34%) (4% + 32%) | D171: 1 | E171: Vacate 32WP | F171: AP-2580 | G171: Eon Agro Industries Limited | H171: Rice | I171: C. difformis, E. crus galli, F.miliacea, L.hexandra, L.chinensis, S.maritimus, C.irria | J171: 600 gm/ha | K171: Rice | C. difformis, E. crus galli, F.miliacea, L.hexandra, L.chinensis, S.maritimus, C.irria | 600 gm/ha | L171: 1 | M171: HRAC B
B172: 9 | C172: Bensulfuron methyl (4%) + Quinclorac (28%) (6% + 34%) (6% + 34%) (4% + 32%) | D172: 2 | E172: Move 40WP | F172: AP-3872 | G172: Nokon Limited | H172: Rice | I172: C. difformis, E. crus galli, M.vaginalis, N.nouchali | J172: 600 gm/ha | K172: Rice | C. difformis, E. crus galli, M.vaginalis, N.nouchali | 600 gm/ha | L172: 1 | M172: HRAC B
B173: 9 | C173: Bensulfuron methyl (4%) + Quinclorac (28%) (6% + 34%) (6% + 34%) (4% + 32%) | D173: 3 | E173: Namir 32WP | F173: AP-4425 | G173: Intefa | H173: Rice | I173: E. crus galli, S. maritimus, M.vaginalis, M.quadrifolis | J173: 600 gm/ha | K173: Rice | E. crus galli, S. maritimus, M.vaginalis, M.quadrifolis | 600 gm/ha | L173: 1 | M173: HRAC B
B174: 9 | C174: Bensulfuron methyl (4%) + Quinclorac (28%) (6% + 34%) (6% + 34%) (4% + 32%) | D174: 4 | E174: Loper 40WP | F174: AP-4824 | G174: Sun Seed Pesticides | H174: Potato | I174: C.dactylon, C.rotundus, C. album, A. spinosus | J174: 100 gm/ha | K174: Potato | C.dactylon, C.rotundus, C. album, A. spinosus | 100 gm/ha | L174: 1 | M174: HRAC B
B175: 9 | C175: Bensulfuron methyl (4%) + Quinclorac (28%) (6% + 34%) (6% + 34%) (4% + 32%) | D175: 1 | E175: Forise 36WP | F175: AP-4825 | G175: Forward International (BD) Ltd. | H175: Tea, Rice | I175: B. hispida, I.cylindrica, C. difformis, E. crus galli, M.vaginalis, C.dectylon | J175: 1.50 Kg/ha; 600 gm/ha | K175: Tea | B. hispida, I.cylindrica | 1.50 Kg/ha Rice | C. difformis, E. crus galli, M.vaginalis, C.dectylon | 600 gm/ha | L175: 2 | M175: HRAC B
...

Sheet Store Grain Insecticide
B2: Registered Store Grain Insecticide Products — up to 81st PTAC Meeting
B4: SL No (Common Name) | C4: Common Name | D4: SL No (Products) | E4: Brand Name | F4: Registration No | G4: Registration Holder | H4: Recommended Crops | I4: Recommended Pests | J4: Dosage Rate | K4: Recommendations (Crop | Pest | Dosage) | L4: No. of Recommendations | M4: MoA Code
B5: 1 | C5: Aluminium Phosphide | D5: 1 | E5: Agriphos 57% | F5: AP-174 | G5: Nokon Limited | H5: Stored grain pest in Rice | I5: Red grain bettle | J5: 4 tables/1000 kg | K5: Stored grain pest in Rice | Red grain bettle | 4 tables/1000 kg | L5: 1 | M5: IRAC 24A
B6: 1 | C6: Aluminium Phosphide | D6: 2 | E6: Alumphos 56% | F6: AP-253 | G6: McDonald Bangladesh (Pvt) Limited | H6: Stored grain pest in Rice | I6: Red grain bettle | J6: 4 tables/1000 kg | K6: Stored grain pest in Rice | Red grain bettle | 4 tables/1000 kg | L6: 1 | M6: IRAC 24A
B7: 1 | C7: Aluminium Phosphide | D7: 3 | E7: Quck-Fume | F7: AP-254 | G7: United Phosphorus (Bangladesh) Ltd | H7: Stored grain pest in Rice | I7: Red grain bettle | J7: 4 tables/1000 kg | K7: Stored grain pest in Rice | Red grain bettle | 4 tables/1000 kg | L7: 1 | M7: IRAC 24A
B8: 1 | C8: Aluminium Phosphide | D8: 4 | E8: Fumitox 56% | F8: AP-530 | G8: National AgriCare Import & Export Ltd | H8: Stored grain pest in Rice | I8: Red grain bettle | J8: 4 tables/1000 kg | K8: Stored grain pest in Rice | Red grain bettle | 4 tables/1000 kg | L8: 1 | M8: IRAC 24A
B9: 1 | C9: Aluminium Phosphide | D9: 5 | E9: Al-cor 56% | F9: AP-661 | G9: Corbel International Limited | H9: Stored grain pest in Rice | I9: Red grain bettle | J9: 4 tables/1000 kg | K9: Stored grain pest in Rice | Red grain bettle | 4 tables/1000 kg | L9: 1 | M9: IRAC 24A
B10: 1 | C10: Aluminium Phosphide | D10: 6 | E10: Gilphos 56% | F10: AP-662 | G10: Gourab Industries Limited | H10: Stored grain pest in Rice | I10: Red grain bettle | J10: 4 tables/1000 kg | K10: Stored grain pest in Rice | Red grain bettle | 4 tables/1000 kg | L10: 1 | M10: IRAC 24A
B11: 1 | C11: Aluminium Phosphide | D11: 7 | E11: Sanphos 56% | F11: AP-663 | G11: Integrated Crop Care Bangladesh | H11: Stored grain pest in Rice | I11: Red grain bettle | J11: 4 tables/1000 kg | K11: Stored grain pest in Rice | Red grain bettle | 4 tables/1000 kg | L11: 1 | M11: IRAC 24A
B12: 1 | C12: Aluminium Phosphide | D12: 8 | E12: Fumiphos 56% | F12: AP-738 | G12: Sun Seed Pesticides | H12: Stored grain pest in Rice | I12: Red grain bettle | J12: 4 tables/1000 kg | K12: Stored grain pest in Rice | Red grain bettle | 4 tables/1000 kg | L12: 1 | M12: IRAC 24A
B13: 1 | C13: Aluminium Phosphide | D13: 9 | E13: Tinder 56% | F13: AP-904 | G13: Maitri Agro Industries | H13: Stored grain pest in Rice | I13: Red grain bettle | J13: 4 tables/1000 kg | K13: Stored grain pest in Rice | Red grain bettle | 4 tables/1000 kg | L13: 1 | M13: IRAC 24A
B14: 1 | C14: Aluminium Phosphide | D14: 10 | E14: Green Fune 56% | F14: AP-905 | G14: Green Bangla Agrovet Ltd. | H14: Stored grain pest in Rice | I14: Red grain bettle | J14: 4 tables/1000 kg | K14: Stored grain pest in Rice | Red grain bettle | 4 tables/1000 kg | L14: 1 | M14: IRAC 24A
B15: 1 | C15: Aluminium Phosphide | D15: 11 | E15: Alphos 56% | F15: AP-908 | G15: Prime Agro Limited | H15: Stored grain pest in Rice | I15: Red grain bettle | J15: 4 tables/1000 kg | K15: Stored grain pest in Rice | Red grain bettle | 4 tables/1000 kg | L15: 1 | M15: IRAC 24A
B16: 1 | C16: Aluminium Phosphide | D16: 12 | E16: Quick balm 56% | F16: AP-910 | G16: Anika Enterprise | H16: Stored grain pest in Rice | I16: Red grain bettle | J16: 4 tables/1000 kg | K16: Stored grain pest in Rice | Red grain bettle | 4 tables/1000 kg | L16: 1 | M16: IRAC 24A
... B92: 4 | C92: Pirimiphos methyl | D92: 6 | E92: Fasmethyl 50EC | F92: AP-4589 | G92: Fasal Agro Industries Ltd. | H92: Rice | I92: Tribolium, Rhizopertha, Sitophilus | J92: 20 ml/L of water | K92: Rice | Tribolium, Rhizopertha, Sitophilus | 20 ml/L of water | L92: 1 | M92: IRAC 1B
B93: Total (visible rows) | E93: =SUBTOTAL(103,E5:E92) -> 88 | L93: =SUBTOTAL(109,L5:L92) -> 91
B95: Source: Department of Agricultural Extension (DAE), Bangladesh — List of Registered Pesticides approved up to the 81st Pesticide Technical Advisory Committee (PTAC) Meeting. Extracted 2026-09-15 from https://dae.gov.bd/pages/files/6922da2a933eb65569e02d1e

Sheet Rodenticide
B2: Registered Rodenticides in Bangladesh — up to 81st PTAC Meeting
B4: SL No (Common Name) | C4: Common Name | D4: SL No (Products) | E4: Brand Name | F4: Registration No | G4: Registration Holder | H4: Recommended Crops | I4: Recommended Pests | J4: Dosage Rate | K4: Recommendations (Crop | Pest | Dosage) | L4: No. of Recommendations | M4: MoA Code
B5: 1 | C5: Bromadiolone | D5: 1 | E5: Lanirat | F5: AP-182 | G5: Syngenta Bangladesh Limited | H5: Crops field | I5: Rats | J5: 2-3 times should be eaten | K5: Crops field | Rats | 2-3 times should be eaten | L5: 1
B6: 1 | C6: Bromadiolone | D6: 2 | E6: Bromapoint | F6: AP-271 | G6: Shetu Pesticides Limited | H6: " | I6: Rats | J6: 2-3 times should be eaten | K6: " | Rats | 2-3 times should be eaten | L6: 1
B7: 1 | C7: Bromadiolone | D7: 3 | E7: Ratox | F7: AP-430 | G7: Auto Crop Care Limited | H7: " | I7: Rats | J7: 2-3 times should be eaten | K7: " | Rats | 2-3 times should be eaten | L7: 1
B8: 1 | C8: Bromadiolone | D8: 4 | E8: Roma | F8: AP-1559 | G8: Eon Agro Industries Limited | H8: " | I8: Rats | J8: 2-3 times should be eaten | K8: " | Rats | 2-3 times should be eaten | L8: 1
B9: 1 | C9: Bromadiolone | D9: 5 | E9: Ratonil | F9: AP-1892 | G9: Green Bangla Agrovet Ltd. | H9: " | I9: Rats | J9: 2-3 times should be eaten | K9: " | Rats | 2-3 times should be eaten | L9: 1
B10: 1 | C10: Bromadiolone | D10: 6 | E10: Ratoma 0.005% RB | F10: AP-5605 | G10: Square Pharmaceuticals Limited | H10: " | I10: Rats | J10: 2-3 times should be eaten | K10: " | Rats | 2-3 times should be eaten | L10: 1
B11: 1 | C11: Bromadiolone | D11: 7 | E11: Rat Finish | F11: AP-6030 | G11: ACI Formulations Limited | H11: " | I11: Rats | J11: 2-3 times should be eaten | K11: " | Rats | 2-3 times should be eaten | L11: 1
B12: 1 | C12: Bromadiolone | D12: 8 | E12: Roban | F12: AP-6031 | G12: Cannon Pest Management (BD) Pvt Ltd. | H12: " | I12: Rats | J12: 2-3 times should be eaten | K12: " | Rats | 2-3 times should be eaten | L12: 1
B13: 1 | C13: Bromadiolone | D13: 9 | E13: Rat Killer | F13: AP-6032 | G13: Sotota Agro Science | H13: " | I13: Rats | J13: 2-3 times should be eaten | K13: " | Rats | 2-3 times should be eaten | L13: 1
B14: 2 | C14: Zinc Phosphide | D14: 1 | E14: Zinc Phosphide | F14: AP-17 | G14: United Phosphorus (Bangladesh) Ltd | H14: " | I14: Rats | J14: 2% bait | K14: " | Rats | 2% bait | L14: 1 | M14: IRAC 24A
B15: 2 | C15: Zinc Phosphide | D15: 2 | E15: Gilphide 80% | F15: AP-739 | G15: Gourab Industries Limited | H15: " | I15: Rats | J15: 2% bait | K15: " | Rats | 2% bait | L15: 1 | M15: IRAC 24A
B16: 2 | C16: Zinc Phosphide | D16: 3 | E16: Commando 80% | F16: AP-915 | G16: Haychem (Bangladesh) Limited | H16: " | I16: Rats | J16: 2% bait | K16: " | Rats | 2% bait | L16: 1 | M16: IRAC 24A
B17: 2 | C17: Zinc Phosphide | D17: 4 | E17: Ratil | F17: AP-916 | G17: Integrated Crop Care Bangladesh | H17: " | I17: Rats | J17: 2% bait | K17: " | Rats | 2% bait | L17: 1 | M17: IRAC 24A
B18: 2 | C18: Zinc Phosphide | D18: 5 | E18: Crystal Zinc 2% | F18: AP-1891 | G18: Green Care Bangladesh | H18: " | I18: Rats | J18: 2% bait | K18: " | Rats | 2% bait | L18: 1 | M18: IRAC 24A
B19: 2 | C19: Zinc Phosphide | D19: 6 | E19: Phonix Brand 2% | F19: AP-5604 | G19: Khaja Chemical Industries | H19: " | I19: Rats | J19: 2% bait | K19: " | Rats | 2% bait | L19: 1 | M19: IRAC 24A
B20: Total (visible rows) | E20: =SUBTOTAL(103,E5:E19) -> 15 | L20: =SUBTOTAL(109,L5:L19) -> 15
B22: Source: Department of Agricultural Extension (DAE), Bangladesh — List of Registered Pesticides approved up to the 81st Pesticide Technical Advisory Committee (PTAC) Meeting. Extracted 2026-09-15 from https://dae.gov.bd/pages/files/6922da2a933eb65569e02d1e

Sheet Bio Pesticide
B2: Registered Bio Pesticicides in Bangladesh — up to 81st PTAC Meeting
B4: SL No (Common Name) | C4: Common Name | D4: SL No (Products) | E4: Brand Name | F4: Registration No | G4: Registration Holder | H4: Recommended Crops | I4: Recommended Pests | J4: Dosage Rate | K4: Recommendations (Crop | Pest | Dosage) | L4: No. of Recommendations | M4: MoA Code
B5: 1 | C5: Abamectin | D5: 1 | E5: Matrixine Plus 5% ME | F5: AP (Bio)-21 | G5: Russell IPM Bangladesh Ltd. | H5: Tea | I5: Red spider mite | J5: 250 ml/ha | K5: Tea | Red spider mite | 250 ml/ha | L5: 1 | M5: IRAC 6
B6: 2 | C6: Cuelure (97%) | D6: 1 | E6: Q-Phero | F6: AP (Bio)-02 | G6: Ispahani Agro Limited | H6: Bitter gourd | I6: Fruit fly | J6: 70 Lures/ha | K6: Bitter gourd | Fruit fly | 70 Lures/ha | L6: 1
B7: 2 | C7: Cuelure (97%) | D7: 2 | E7: Bactro-D | F7: AP (Bio)-03 | G7: Ispahani Agro Limited | H7: Mango, Guava | I7: Fruit fly | J7: 80 Lures/ha | K7: Mango, Guava | Fruit fly | 80 Lures/ha | L7: 1
B8: 2 | C8: Cuelure (97%) | D8: 3 | E8: AT Cuelure '69 | F8: AP (Bio)-28 | G8: Agritech 69 Limited | H8: Bitter gourd | I8: Fruit fly | J8: 70 Lures/ha | K8: Bitter gourd | Fruit fly | 70 Lures/ha | L8: 1
B9: 2 | C9: Cuelure (97%) | D9: 4 | E9: Tabiz Pheromone Trap | F9: AP (Bio)-29 | G9: ACP Bangladesh | H9: Bitter gourd | I9: Fruit fly | J9: 100 Lures/ha | K9: Bitter gourd | Fruit fly | 100 Lures/ha | L9: 1
